Workbook
Name Sistema: [2]Explicación!$B$132:$B$144

Sheet MP control
A2: Arian Silver de México S.A. de C.V. Planeación Mantenimiento Mina Administración de flotilla vehicular 2026
A7: INFORMACIÓN GENERAL | L7: Intervalos de mantenimiento | P7: Programación
A8: Unidad | B8: Ubicación | C8: Propietario | D8: Departamento | E8: Cuenta contable | F8: Modelo | G8: Combustible | H8: Placas | I8: No. Serie | J8: Medida de neumáticos | K8: Botiquín PA | L8: Int días | M8: Int servicio | N8: Km Prom diario | O8: Km actuales | P8: Km Último servicio | Q8: Fecha ultimo servicio | R8: Km proximo servicio | S8: Servicio por KM | T8: Km para servicio | U8: Servicio por T | V8: Pronóstico serv
A9: ASM-002HiluxMedio Ambiente ZH-3163-B | B9: Mina | C9: Arian Silver de México | D9: Medio Ambiente | E9: 8019-548-901 | F9: 2007 | G9: Diésel | H9: ZH-3153-B | I9: 1D7HW48P87S256272 | J9: LT/265/70R17 | K9: SI | L9: 180 | M9: 10000 | N9: =+'Captura check list'!BO8 -> 35.857143 | O9: =+'Captura check list'!BQ8 -> 120763 | P9: 119728 | Q9: 46090 | R9: =+P9+M9 -> 129728 | S9: =TODAY()+(T9/N9) -> 46387.02 | T9: =+R9-O9 -> 8965 | U9: =+Q9+L9 -> 46270 | V9: =IF(S9>U9,U9,S9) -> 46270
A10: ASM-006FrontierMedio Ambiente ZH-3161-B | B10: Mina | C10: Arian Silver de México | D10: Medio Ambiente | E10: 8019-400-922 | F10: 2016 | G10: Gasolina | H10: ZH-3161-B | I10: 3N6AD33C4GK892141 | J10: AT/205R16C | K10: SI | L10: 180 | M10: 10000 | N10: =+'Captura check list'!BO9 -> 45 | O10: =+'Captura check list'!BQ9 -> 357833 | P10: 356944 | Q10: 46092 | R10: =+P10+M10 -> 366944 | S10: =TODAY()+(T10/N10) -> 46339.467 | T10: =+R10-O10 -> 9111 | U10: =+Q10+L10 -> 46272 | V10: =IF(S10>U10,U10,S10) -> 46272
A11: ASM-007NP 300LaboratorioZH-3160-B | B11: Planta | C11: Arian Silver de México | D11: Laboratorio | E11: 8012-548-390 | F11: 2016 | G11: Gasolina | H11: ZH-3160-B | I11: 3N6AD33C5GK814774 | K11: SI | L11: 180 | M11: 10000 | N11: =+'Captura check list'!BO10 -> 15 | O11: =+'Captura check list'!BQ10 -> 327593 | P11: 327333 | Q11: 46092 | R11: =+P11+M11 -> 337333 | S11: =TODAY()+(T11/N11) -> 46786.333 | T11: =+R11-O11 -> 9740 | U11: =+Q11+L11 -> 46272 | V11: =IF(S11>U11,U11,S11) -> 46272
A12: ASM-008HiluxOperación Mina TP-0477-H | B12: Mina | C12: Huur | D12: Operación Mina | E12: 8019-548-190 | F12: 2019 | G12: Diésel | H12: ZH-3163-B | I12: MR0FA8CD8K3900944 | K12: SI | L12: 90 | M12: 5000 | N12: =+'Captura check list'!BO11 -> 110 | O12: =+'Captura check list'!BQ11 -> 25955 | P12: 23940 | Q12: 46107 | R12: =+P12+M12 -> 28940 | S12: =TODAY()+(T12/N12) -> 46164.136 | T12: =+R12-O12 -> 2985 | U12: =+Q12+L12 -> 46197 | V12: =IF(S12>U12,U12,S12) -> 46164.136
A13: ASM-009NissanVersaVEH-746-D | B13: Mina | C13: Huur | D13: Planeación | E13: 8012-548-150 | F13: 2025 | G13: Gasolina | H13: VEH-746-D | I13: 3N1CN8AE9SK599731 | K13: SI | L13: 180 | M13: 10000 | N13: =+'Captura check list'!BO12 -> 181.28571 | O13: =+'Captura check list'!BQ12 -> 53460 | P13: 51006 | Q13: 46112 | R13: =+P13+M13 -> 61006 | S13: =TODAY()+(T13/N13) -> 46178.625 | T13: =+R13-O13 -> 7546 | U13: =+Q13+L13 -> 46292 | V13: =IF(S13>U13,U13,S13) -> 46178.625
A14: ASM-010ChevroletAveoUXS-682-E | B14: Mina | C14: Huur | D14: Operación Mina | E14: 8019-548-190 | F14: 2025 | G14: Gasolina | H14: UXS-682-E | I14: LZWPRMGN6SF107290 | K14: SI | L14: 180 | M14: 10000 | N14: =+'Captura check list'!BO13 -> 228.85714 | O14: =+'Captura check list'!BQ13 -> 22487 | P14: 19680 | Q14: 46094 | R14: =+P14+M14 -> 29680 | S14: =TODAY()+(T14/N14) -> 46168.43 | T14: =+R14-O14 -> 7193 | U14: =+Q14+L14 -> 46274 | V14: =IF(S14>U14,U14,S14) -> 46168.43
A15: ASM-011Ram 4000Mantenimiento PlantaZH-3152-B | B15: Planta | C15: Arian Silver de México | D15: Mantenimiento Planta | E15: 8019-548-390 | F15: 2021 | G15: Gasolina | H15: ZH-3152-B | I15: 3C7WRAKT6MG570165 | K15: SI | L15: 180 | M15: 10000 | N15: =+'Captura check list'!BO14 -> 56.428571 | O15: =+'Captura check list'!BQ14 -> 45921 | P15: 42400 | Q15: 45954 | R15: =+P15+M15 -> 52400 | S15: =TODAY()+(T15/N15) -> 46251.818 | T15: =+R15-O15 -> 6479 | U15: =+Q15+L15 -> 46134 | V15: =IF(S15>U15,U15,S15) -> 46134
A16: ASM-012L200 Gerencia GeneralZD-1550-B | B16: Mina | C16: Arian Silver de México | D16: Administración | E16: 8019-548-901 | F16: 2022 | G16: Diésel | H16: ZD-1550-B | I16: MMBNLV56XNH055968 | K16: SI | L16: 90 | M16: 5000 | N16: =+'Captura check list'!BO15 -> 144.85714 | O16: =+'Captura check list'!BQ15 -> 76146 | P16: 74677 | Q16: 46074 | R16: =+P16+M16 -> 79677 | S16: =TODAY()+(T16/N16) -> 46161.376 | T16: =+R16-O16 -> 3531 | U16: =+Q16+L16 -> 46164 | V16: =IF(S16>U16,U16,S16) -> 46161.376
A17: ASM-013L200 Seguridad IndustrialZD-1551-B | B17: Mina | C17: Arian Silver de México | D17: Seguridad Industiral | E17: 8019-548-914 | F17: 2022 | G17: Diésel | H17: ZD-1551-B | I17: MMBNLV563NH056251 | K17: SI | L17: 90 | M17: 5000 | N17: =+'Captura check list'!BO16 -> 43.857143 | O17: =+'Captura check list'!BQ16 -> 55007 | P17: 52573 | Q17: 46035 | R17: =+P17+M17 -> 57573 | S17: =TODAY()+(T17/N17) -> 46195.508 | T17: =+R17-O17 -> 2566 | U17: =+Q17+L17 -> 46125 | V17: =IF(S17>U17,U17,S17) -> 46125
A18: ASM-014L200 GeologíaZD-1552-B | B18: Mina | C18: Arian Silver de México | D18: Geología | E18: 8012-548-140 | F18: 2022 | G18: Diésel | H18: ZD-1552-B | I18: MMBNLV569NH055993 | K18: SI | L18: 90 | M18: 5000 | N18: =+'Captura check list'!BO17 -> 124.71429 | O18: =+'Captura check list'!BQ17 -> 130876 | P18: 127883 | Q18: 46092 | R18: =+P18+M18 -> 132883 | S18: =TODAY()+(T18/N18) -> 46153.093 | T18: =+R18-O18 -> 2007 | U18: =+Q18+L18 -> 46182 | V18: =IF(S18>U18,U18,S18) -> 46153.093
A19: ASM-015YarisAdministraciónZHY-780-E | B19: Mina | C19: Arian Silver de México | D19: Administración | E19: 8019-548-901 | F19: 2023 | G19: Gasolina | H19: ZHY-780-E | I19: MR2BF8C38P0005090 | K19: SI | L19: 180 | M19: 10000 | N19: =+'Captura check list'!BO18 -> 210.28571 | O19: =+'Captura check list'!BQ18 -> 161077 | P19: 150000 | Q19: 46020 | R19: =+P19+M19 -> 160000 | S19: =TODAY()+(T19/N19) -> 46131.878 | T19: =+R19-O19 -> -1077 | U19: =+Q19+L19 -> 46200 | V19: =IF(S19>U19,U19,S19) -> 46131.878
A20: ASM-016Ram 700 Operación PlantaYW-8191-D | B20: Planta | C20: Arian Silver de México | D20: Operación Planta | E20: 8012-548-390 | F20: 2024 | G20: Gasolina | H20: YW-8191-D | I20: 9BD281H59PYY69987 | K20: SI | L20: 180 | M20: 10000 | N20: =+'Captura check list'!BO19 -> 216 | O20: =+'Captura check list'!BQ19 -> 106610 | P20: 96515 | Q20: 46035 | R20: =+P20+M20 -> 106515 | S20: =TODAY()+(T20/N20) -> 46136.56 | T20: =+R20-O20 -> -95 | U20: =+Q20+L20 -> 46215 | V20: =IF(S20>U20,U20,S20) -> 46136.56
A21: ASM-017HiluxMantenimiento Eléctrico Mina TK-9722-H | B21: Mina | C21: Huur | D21: Mantenimiento Mina | E21: 8019-548-190 | F21: 2024 | G21: Diésel | H21: TK-9722-H | I21: MR0DA3CXR4007222 | K21: SI | L21: 90 | M21: 5000 | N21: =+'Captura check list'!BO20 -> 118.85714 | O21: =+'Captura check list'!BQ20 -> 51812 | P21: 49627 | Q21: 46108 | R21: =+P21+M21 -> 54627 | S21: =TODAY()+(T21/N21) -> 46160.684 | T21: =+R21-O21 -> 2815 | U21: =+Q21+L21 -> 46198 | V21: =IF(S21>U21,U21,S21) -> 46160.684
A22: ASM-018KiaRioPCZ-11-91 | B22: Planta | C22: Huur | D22: Mantenimiento Planta | E22: 8019-548-390 | F22: 2022 | G22: Gasolina | H22: PCZ-11-91 | I22: 3KPA24BC4NE456823 | K22: SI | L22: 180 | M22: 10000 | N22: =+'Captura check list'!BO21 -> 178.57143 | O22: =+'Captura check list'!BQ21 -> 98391 | P22: 96540 | Q22: 45953 | R22: =+P22+M22 -> 106540 | S22: =TODAY()+(T22/N22) -> 46182.634 | T22: =+R22-O22 -> 8149 | U22: =+Q22+L22 -> 46133 | V22: =IF(S22>U22,U22,S22) -> 46133
... A31: ASM-027HiluxOperación Mina TN-920-H | B31: Mina | C31: Huur | D31: Operación Mina | E31: 8019-548-190 | F31: 2025 | G31: Diésel | H31: TN-0201-H | I31: MR0DA3CD9S4009937 | K31: SI | L31: 90 | M31: 5000 | N31: =+'Captura check list'!BO30 -> 160.71429 | O31: =+'Captura check list'!BQ30 -> 16332 | P31: 11627 | Q31: 46080 | R31: =+P31+M31 -> 16627 | S31: =TODAY()+(T31/N31) -> 46138.836 | T31: =+R31-O31 -> 295 | U31: =+Q31+L31 -> 46170 | V31: =IF(S31>U31,U31,S31) -> 46138.836

Sheet Captura check  list
A2: #VALUE!
C5: 2025 | N5: 2026
A6: CAPTURA DE CHECK LIST VEHICULAR | C6: 45950 | D6: 45957 | E6: 45964 | F6: 45971 | G6: 45978 | H6: 45985 | I6: 45992 | J6: 45999 | K6: 46006 | L6: 46013 | M6: 46020 | N6: 46027 | O6: 46034 | P6: 46041 | Q6: 46048 | R6: 46055 | S6: 46062 | T6: 46069 | U6: 46076 | V6: 46083 | W6: 46090 | X6: 46097 | Y6: 46104 | Z6: 46111 | AA6: 46118 | AB6: 46125 | AC6: 46132 | AD6: 46139 | AE6: 46146 | AF6: 46153 | AG6: 46160 | AH6: 46167 | AI6: 46174 | AJ6: 46181 | AK6: 46188 | AL6: 46195 | AM6: 46202 | AN6: 46209 | AO6: 46216 | AP6: 46223 | AQ6: 46230 | AR6: 46237 | AS6: 46244 | AT6: 46251 | AU6: 46258 | AV6: 46265 | AW6: 46272 | AX6: 46279 | AY6: 46286 | AZ6: 46293 | BA6: 46300 | BB6: 46307 | BC6: 46314 | BD6: 46321 | BE6: 46328 | BF6: 46335 | BG6: 46342 | BH6: 46349 | BI6: 46356 | BJ6: 46363 | BK6: 46370 | BL6: 46377 | BM6: 46384 | BO6: Promedio km recorridos
BO7: X Diario | BP7: X Semanal | BQ7: actuales
A8: ASM-002HiluxMedio Ambiente ZH-3163-B | C8: 330862 | D8: 331050 | E8: 331163 | F8: 331303 | G8: 331457 | H8: 331520 | I8: 331657 | J8: 331754 | K8: 331943 | L8: 331987 | M8: 332031 | N8: 332031 | O8: 332032 | P8: 332038 | Q8: 332038 | R8: 118955 | S8: =+AVERAGE(T8,R8) -> 119045.5 | T8: 119136 | U8: 119387 | V8: 119547 | W8: 119728 | X8: =+W8+181 -> 119909 | Y8: 120050 | Z8: 120209 | AA8: 120352 | AB8: 120568 | AC8: 120763 | BO8: =+BP8/7 -> 35.857143 | BP8: =BO35 -> 251 | BQ8: =MAX(R8:BM8) -> 120763
A9: ASM-006FrontierMedio Ambiente ZH-3161-B | C9: 353892 | D9: 354060 | E9: 354209 | F9: 354421 | G9: 354602 | H9: 354661 | I9: =+H9+59 -> 354720 | J9: =AVERAGE(I9,K9) -> 355058.5 | K9: 355397 | L9: 355457.5 | M9: 355518 | N9: 355587 | O9: 355687 | P9: 355794 | Q9: =+P9+118 -> 355912 | R9: =+Q9+118 -> 356030 | S9: 356147 | T9: 356335 | U9: 356464 | V9: 356581 | W9: 356780 | X9: 357095 | Y9: 357324 | Z9: 357473 | AA9: 357555 | AB9: 357706 | AC9: 357833 | BO9: =+BP9/7 -> 45 | BP9: =BO36 -> 315 | BQ9: =MAX(C9:BM9) -> 357833
A10: ASM-007NP 300LaboratorioZH-3160-B | C10: 325641 | D10: 325746 | E10: =+D10+77 -> 325823 | F10: =+E10+77 -> 325900 | G10: =+F10+77 -> 325977 | H10: =+G10+77 -> 326054 | I10: =+H10+77 -> 326131 | J10: =+I10+77 -> 326208 | K10: =+J10+77 -> 326285 | L10: 326361 | M10: 326437 | N10: 326513 | O10: 326572 | P10: =+O10+59 -> 326631 | Q10: =+P10+59 -> 326690 | R10: =+Q10+59 -> 326749 | S10: =+R10+59 -> 326808 | T10: =+S10+59 -> 326867 | U10: =+T10+59 -> 326926 | V10: =+U10+59 -> 326985 | W10: =+V10+59 -> 327044 | X10: =+W10+59 -> 327103 | Y10: =+X10+70 -> 327173 | Z10: =+Y10+105 -> 327278 | AA10: =+Z10+105 -> 327383 | AB10: =+AA10+105 -> 327488 | AC10: =+AB10+105 -> 327593 | BO10: =+BP10/7 -> 15 | BP10: =BO37 -> 105 | BQ10: =MAX(C10:BM10) -> 327593
A11: ASM-008HiluxOperación Mina TP-0477-H | C11: 13601.5 | D11: 14093 | E11: 14389 | F11: 15145 | G11: 15638 | H11: 16122 | I11: =+H11+488 -> 16610 | J11: =AVERAGE(I11,K11) -> 17042 | K11: 17474 | L11: 17829.5 | M11: 18185 | N11: 18541 | O11: 19004 | P11: 19716 | Q11: =+P11+302 -> 20018 | R11: =+Q11+302 -> 20320 | S11: 20621 | T11: 21391 | U11: 21811 | V11: =+U11+420 -> 22231 | W11: 22811 | X11: 23426 | Y11: 23932 | Z11: 24381 | AA11: 24968 | AB11: 25486 | AC11: 25955 | BO11: =+BP11/7 -> 110 | BP11: =BO38 -> 770 | BQ11: =MAX(C11:BM11) -> 25955
A12: ASM-009NissanVersaVEH-746-D | C12: 32948 | D12: 33615 | E12: 34628 | F12: 35560 | G12: =AVERAGE(H12,F12) -> 36069 | H12: 36578 | I12: 37371 | J12: 37390 | K12: 38949 | L12: 39717.5 | M12: 40486 | N12: 40892 | O12: 41475 | P12: =+O12+583 -> 42058 | Q12: =+P12+1019 -> 43077 | R12: =+Q12+1019 -> 44096 | S12: 45114 | T12: 46010 | U12: 46742 | V12: 48011 | W12: 48738 | X12: 49740 | Y12: 50327 | Z12: 51006 | AA12: 51922 | AB12: 52748 | AC12: 53460 | BO12: =+BP12/7 -> 181.28571 | BP12: =BO39 -> 1269 | BQ12: =MAX(C12:BM12) -> 53460
A13: ASM-010ChevroletAveoUXS-682-E | C13: 5555.5 | D13: 6392 | E13: 6851 | F13: 8403 | G13: 9241 | H13: =+G13+531 -> 9772 | I13: =+H13+531 -> 10303 | J13: =+I13+531 -> 10834 | K13: =+J13+531 -> 11365 | L13: =+K13+531 -> 11896 | M13: =+L13+531 -> 12427 | N13: =+M13+531 -> 12958 | O13: =+N13+531 -> 13489 | P13: 14021 | Q13: =+P13+545 -> 14566 | R13: =+Q13+545 -> 15111 | S13: 15657 | T13: 15657 | U13: 17259 | V13: 18509 | W13: 19043 | X13: 20039 | Y13: 20972 | Z13: 21332 | AA13: 21847 | AB13: =+AA13+320 -> 22167 | AC13: =+AB13+320 -> 22487 | BO13: =+BP13/7 -> 228.85714 | BP13: =BO40 -> 1602 | BQ13: =MAX(C13:BM13) -> 22487
A14: ASM-011Ram 4000Mantenimiento PlantaZH-3152-B | C14: 42320 | D14: 42417 | E14: 42562 | F14: =+E14+91 -> 42653 | G14: =+F14+91 -> 42744 | H14: 42834 | I14: 43143 | J14: 43285 | K14: =+J14+142 -> 43427 | L14: 43469 | M14: 43511 | N14: 43552 | O14: 43660 | P14: =+O14+108 -> 43768 | Q14: =+P14+104 -> 43872 | R14: =+Q14+104 -> 43976 | S14: =+R14+104 -> 44080 | T14: 44202 | U14: 44597 | V14: =+U14+97 -> 44694 | W14: =+V14+97 -> 44791 | X14: 44888 | Y14: 45139 | Z14: 45250 | AA14: 45434 | AB14: 45742 | AC14: 45921 | BO14: =+BP14/7 -> 56.428571 | BP14: =BO41 -> 395 | BQ14: =MAX(C14:BM14) -> 45921
A15: ASM-012L200 Gerencia GeneralZD-1550-B | C15: =D15-327 -> 65320 | D15: 65647 | E15: =AVERAGE(D15,F15) -> 65716 | F15: 65785 | G15: =+F15+69 -> 65854 | H15: =+G15+330 -> 66184 | I15: =+H15+330 -> 66514 | J15: =+AVERAGE(I15,K15) -> 66605.5 | K15: 66697 | L15: 67147 | M15: 67597 | N15: =+M15+1014 -> 68611 | O15: =+N15+1014 -> 69625 | P15: =+O15+1014 -> 70639 | Q15: =+P15+1014 -> 71653 | R15: =+Q15+1014 -> 72667 | S15: =+R15+1014 -> 73681 | T15: =+S15+1014 -> 74695 | U15: 74695 | V15: =+AVERAGE(W15,U15) -> 74848 | W15: 75001 | X15: 75596 | Y15: 75646 | Z15: 75685 | AA15: 75724 | AB15: 75908 | AC15: 76146 | BO15: =+BP15/7 -> 144.85714 | BP15: =BO42 -> 1014 | BQ15: =MAX(C15:BM15) -> 76146
A16: ASM-013L200 Seguridad IndustrialZD-1551-B | C16: 50189 | D16: 50725 | E16: 50865 | F16: 51192 | G16: 51270 | H16: 51445 | I16: =+H16+175 -> 51620 | J16: =+AVERAGE(I16,K16) -> 51719.5 | K16: 51819 | L16: 51919 | M16: 52019 | N16: 52567 | O16: =+N16+100 -> 52667 | P16: =+O16+100 -> 52767 | Q16: =+P16+114 -> 52881 | R16: =+Q16+114 -> 52995 | S16: 53109 | T16: 53366 | U16: 53586 | V16: =+AVERAGE(W16,U16) -> 53760 | W16: 53934 | X16: =+W16+174 -> 54108 | Y16: 54415 | Z16: 54495 | AA16: 54754 | AB16: 54854 | AC16: 55007 | BO16: =+BP16/7 -> 43.857143 | BP16: =BO43 -> 307 | BQ16: =MAX(C16:BM16) -> 55007
A17: ASM-014L200 GeologíaZD-1552-B | C17: 118578 | D17: 118689 | E17: 119425 | F17: 119837 | G17: 120318 | H17: 120318 | I17: 121033 | J17: =+AVERAGE(I17,K17) -> 121409 | K17: 121785 | L17: 122280.5 | M17: 122776 | N17: 123272 | O17: 123752 | P17: 124625 | Q17: =+P17+307 -> 124932 | R17: =+Q17+307 -> 125239 | S17: 125546 | T17: 126158 | U17: 126678 | V17: =+AVERAGE(W17,U17) -> 127182.5 | W17: 127687 | X17: 128321 | Y17: 128865 | Z17: 129366 | AA17: 129887 | AB17: 130427 | AC17: 130876 | BO17: =+BP17/7 -> 124.71429 | BP17: =BO44 -> 873 | BQ17: =MAX(C17:BM17) -> 130876
A18: ASM-015YarisAdministraciónZHY-780-E | C18: 145724 | D18: 145880 | E18: 146792 | F18: 147328 | G18: 148158 | H18: 148382 | I18: 149082 | J18: =+AVERAGE(I18,K18) -> 149338.5 | K18: 149595 | L18: 149978 | M18: 150361 | N18: 150761 | O18: =+N18+400 -> 151161 | P18: 152633 | Q18: =+P18+592 -> 153225 | R18: =+Q18+592 -> 153817 | S18: =+R18+592 -> 154409 | T18: 155000 | U18: 155062 | V18: =+AVERAGE(W18,U18) -> 155854 | W18: 156646 | X18: 157438 | Y18: 158265 | Z18: 159151 | AA18: 159764 | AB18: 160522 | AC18: 161077 | BO18: =+BP18/7 -> 210.28571 | BP18: =BO45 -> 1472 | BQ18: =MAX(C18:BM18) -> 161077
A19: ASM-016Ram 700 Operación PlantaYW-8191-D | C19: 85229 | D19: 86192 | E19: =AVERAGE(D19,F19) -> 87195.5 | F19: 88199 | G19: =+AVERAGE(F19,H19) -> 89123 | H19: 90047 | I19: 90957 | J19: =+AVERAGE(I19,K19) -> 91943.5 | K19: 92930 | L19: 93736.5 | M19: 94543 | N19: 95350 | O19: 96267 | P19: =+O19+900 -> 97167 | Q19: =+P19+702 -> 97869 | R19: =+Q19+702 -> 98571 | S19: 99272 | T19: =+S19+702 -> 99974 | U19: =+T19+702 -> 100676 | V19: =+AVERAGE(W19,U19) -> 101741.5 | W19: 102807 | X19: 104319 | Y19: 104843 | Z19: =+AVERAGE(AA19,Y19) -> 105726.5 | AA19: 106610 | AB19: 50980 | AC19: 51503 | BO19: =+BP19/7 -> 216 | BP19: =BO46 -> 1512 | BQ19: =MAX(C19:BM19) -> 106610
A20: ASM-017HiluxMantenimiento Eléctrico Mina TK-9722-H | C20: 37255 | D20: 37779 | E20: 38329 | F20: 38945 | G20: 39609 | H20: 40086 | I20: 40813 | J20: =+AVERAGE(I20,K20) -> 41284 | K20: 41755 | L20: 42294.5 | M20: 42834 | N20: 43316 | O20: 43792 | P20: 44461 | Q20: =+P20+529 -> 44990 | R20: =+Q20+529 -> 45519 | S20: 46047 | T20: 46687 | U20: 47272 | V20: 48006 | W20: 48381 | X20: 49004 | Y20: =+X20+623 -> 49627 | Z20: 49705 | AA20: 50279 | AB20: 50980 | AC20: 51812 | BO20: =+BP20/7 -> 118.85714 | BP20: =BO47 -> 832 | BQ20: =MAX(C20:BM20) -> 51812
A21: ASM-018KiaRioPCZ-11-91 | C21: 83502 | D21: =+AVERAGE(E21,C21) -> 83772 | E21: 84042 | F21: 84734 | G21: 85392 | H21: =+G21+658 -> 86050 | I21: 86555 | J21: 87356 | K21: =+J21+801 -> 88157 | L21: 88611 | M21: 89065 | N21: 89519 | O21: =+N21+454 -> 89973 | P21: =+O21+454 -> 90427 | Q21: =+P21+452 -> 90879 | R21: =+Q21+452 -> 91331 | S21: =+R21+452 -> 91783 | T21: 92235 | U21: 93485 | V21: =+AVERAGE(W21,U21) -> 94128 | W21: 94771 | X21: =+W21+643 -> 95414 | Y21: 96060 | Z21: =+AVERAGE(AA21,Y21) -> 96540 | AA21: 97020 | AB21: =+AA21+480 -> 97500 | AC21: 98391 | BO21: =+BP21/7 -> 178.57143 | BP21: =BO48 -> 1250 | BQ21: =MAX(C21:BM21) -> 98391
A22: ASM-019HiluxPlaneaciónTJ-7355-F | C22: 132451 | D22: 132615 | E22: 132850 | F22: 132980 | G22: 132244 | H22: 133408 | I22: =+H22+147 -> 133555 | J22: =+I22+147 -> 133702 | K22: 133856 | L22: 134059.5 | M22: 134263 | N22: 134559 | O22: =+N22+296 -> 134855 | P22: 134926 | Q22: =+P22+164 -> 135090 | R22: =+Q22+164 -> 135254 | S22: 135419 | T22: 135820 | U22: 136064 | V22: 136284 | W22: 136461 | X22: 136728 | Y22: 137251 | Z22: 137423 | AA22: 137541 | AB22: 137709 | AC22: 137874 | BO22: =+BP22/7 -> 74.714286 | BP22: =BO49 -> 523 | BQ22: =MAX(C22:BM22) -> 137874
A23: ASM-020HiluxExploraciónP TG7053-H | C23: 86351 | D23: 87405 | E23: 88177 | F23: 88886 | G23: 89944 | H23: 90485 | I23: =+H23+541 -> 91026 | J23: 92338 | K23: 93226 | L23: 94106 | M23: 94986 | N23: 95786 | O23: =+N23+800 -> 96586 | P23: 96600 | Q23: =+P23+546 -> 97146 | R23: =+Q23+546 -> 97692 | S23: 98239 | T23: 99131 | U23: 100011 | V23: =+AVERAGE(W23,U23) -> 100833.5 | W23: 101656 | X23: 102588 | Y23: 103554 | Z23: 104314 | AA23: 105285 | AB23: 106376 | AC23: =+AB23+1091 -> 107467 | BO23: =+BP23/7 -> 155.85714 | BP23: =BO50 -> 1091 | BQ23: =MAX(C23:BM23) -> 107467
A24: ASM-021HiluxPlaneaciónTM-33-95-G | C24: 51456 | D24: 51663 | E24: 51982 | F24: 52278 | G24: 52501 | H24: 52761 | I24: 53143 | J24: =+AVERAGE(I24,K24) -> 53428 | K24: 53713 | L24: 53967.5 | M24: 54222 | N24: 54507 | O24: 54718 | P24: 55206 | Q24: 55486 | R24: =+Q24+280 -> 55766 | S24: =+R24+280 -> 56046 | T24: 56367 | U24: 56617 | V24: =+AVERAGE(W24,U24) -> 56873.5 | W24: 57130 | X24: =+W24+829 -> 57959 | Y24: 57959 | Z24: 58128 | AA24: 58352 | AB24: 58606 | AC24: 58774 | BO24: =+BP24/7 -> 118.42857 | BP24: =BO51 -> 829 | BQ24: =MAX(C24:BM24) -> 58774
A25: ASM-022YarisRelaciones Comunitarias UWY-713-D | C25: 86633 | D25: 87268 | E25: 87868 | F25: 88903 | G25: 89714 | H25: 90000 | I25: 90559 | J25: =+AVERAGE(I25,K25) -> 91328.5 | K25: 92098 | L25: 92718 | M25: 93338 | N25: 93732 | O25: 94553 | P25: 95309 | Q25: =+P25+579 -> 95888 | R25: =+Q25+579 -> 96467 | S25: 97046 | T25: 97848 | U25: 98698 | V25: 99397 | W25: 100284 | X25: 101001 | Y25: 101920 | Z25: 102810 | AA25: 103660 | AB25: 104381 | AC25: 104782 | BO25: =+BP25/7 -> 131.28571 | BP25: =BO52 -> 919 | BQ25: =MAX(C25:BM25) -> 104782
A26: ASM-023SeatAtecaUYM-047-C (VERSA PLATA PROVISIONAL) | C26: 126520 | D26: 127290 | E26: 127774 | F26: 128271 | G26: =AVERAGE(H26,F26) -> 128723 | H26: 129175 | I26: =+H26+452 -> 129627 | J26: =+I26+452 -> 130079 | K26: =+J26+452 -> 130531 | L26: 130951 | M26: 131371 | N26: 131791 | O26: =+N26+420 -> 132211 | P26: =+O26+420 -> 132631 | Q26: 133051 | R26: =+S26-440 -> 24603 | S26: =+T26-440 -> 25043 | T26: =+U26-440 -> 25483 | U26: =+V26-440 -> 25923 | V26: =+W26-440 -> 26363 | W26: 26803 | X26: 27313 | Y26: 27821 | Z26: =+AVERAGE(AA26,Y26) -> 28269.5 | AA26: 28718 | AB26: 29416 | AC26: =+AB26+698 -> 30114 | BO26: =+BP26/7 -> 99.714286 | BP26: =BO53 -> 698 | BQ26: =MAX(R26:BM26) -> 30114
A27: ASM-024Frision T8 4x4Seguridad PatrimonialYW-7900-D | C27: 169564 | D27: 170567 | E27: 171866 | F27: 173334 | G27: =+F27+752 -> 174086 | H27: =+G27+752 -> 174838 | I27: =+H27+752 -> 175590 | J27: =+I27+752 -> 176342 | K27: =+J27+752 -> 177094 | L27: =+K27+752 -> 177846 | M27: =+L27+752 -> 178598 | N27: =+M27+752 -> 179350 | ... P27: =+O27+752 -> 180854 | Q27: 181603 | R27: =+AVERAGE(Q27,S27) -> 181672.5 | S27: 181742 | T27: 183455 | U27: =+T27+1200 -> 184655 | V27: =+AVERAGE(W27,U27) -> 185509 | W27: 186363 | X27: 187707 | Y27: 189251 | Z27: 190402 | AA27: 191478 | AB27: 192568 | AC27: 193129 | BO27: =+BP27/7 -> 244.71429 | BP27: =BO54 -> 1713 | BQ27: =MAX(C27:BM27) -> 193129
A28: ASM-025JACX200Administración-ZA-6811-D | C28: 46409 | D28: 47029 | E28: 47520 | F28: 48027 | G28: 48488 | H28: 48658 | I28: 49785 | J28: =+AVERAGE(K28,I28) -> 50301.5 | K28: 50818 | L28: 50818 | M28: 51431.5 | N28: 52045 | O28: 52567 | P28: 53165 | Q28: =+P28+536 -> 53701 | R28: =+Q28+536 -> 54237 | S28: 54773 | T28: =+S28+536 -> 55309 | U28: 56328 | V28: =+AVERAGE(W28,U28) -> 56895.5 | W28: 57463 | X28: 58064 | Y28: 58456 | Z28: 59023 | AA28: 59212 | AB28: 59661 | AC28: 59994 | BO28: =+BP28/7 -> 145.57143 | BP28: =BO55 -> 1019 | BQ28: =MAX(C28:BM28) -> 59994
A29: ASM-026HiluxGeología TL-8939-H | C29: 44637 | D29: 45271 | E29: 46725 | F29: 47674 | G29: =+AVERAGE(H29,F29) -> 48514.5 | H29: 49355 | I29: 50694 | J29: =+AVERAGE(I29,K29) -> 51295.5 | K29: 51897 | L29: 51897 | M29: 52497 | N29: 53097 | O29: =+N29+600 -> 53697 | P29: =+O29+600 -> 54297 | Q29: =+P29+1378.75 -> 55675.75 | R29: =+Q29+1378.75 -> 57054.5 | S29: =+R29+1378.75 -> 58433.25 | T29: 59812 | U29: 60502 | V29: =+AVERAGE(W29,U29) -> 61237.5 | W29: 61973 | X29: 63458 | Y29: 64394 | Z29: 65537 | AA29: 65919 | AB29: 67340 | AC29: 68103 | BO29: =+BP29/7 -> 212.14286 | BP29: =BO56 -> 1485 | BQ29: =MAX(C29:BM29) -> 68103
A30: ASM-027HiluxOperación Mina TN-920-H | C30: 1450 | D30: 1643 | E30: 1947 | F30: 2819 | G30: 3329 | H30: =+G30+510 -> 3839 | I30: =+H30+510 -> 4349 | J30: =+AVERAGE(I30,K30) -> 5102 | K30: 5855 | L30: 6413 | M30: 6971 | N30: 7529 | O30: 7758 | P30: 8824 | Q30: =+P30+319 -> 9143 | R30: =+Q30+319 -> 9462 | S30: 9782 | T30: 10539 | U30: =+T30+544 -> 11083 | V30: =+U30+544 -> 11627 | W30: 12171 | X30: =+W30+544 -> 12715 | Y30: 13453 | Z30: 14218 | AA30: 14775 | AB30: 15900 | AC30: 16332 | BO30: =+BP30/7 -> 160.71429 | BP30: =BO57 -> 1125 | BQ30: =MAX(C30:BM30) -> 16332
A31: Dakota (Provisional) | T31: 332225 | U31: =+AVERAGE(V31,T31) -> 332287.5 | V31: 332350
C32: 2025
A33: Km recorridos en la semana | C33: 45950 | D33: 45957 | E33: 45964 | F33: 45971 | G33: 45978 | H33: 45985 | I33: 45992 | J33: 45999 | K33: 46006 | L33: 46013 | M33: 46020 | N33: 46027 | O33: 46034 | P33: 46041 | Q33: 46048 | R33: 46055 | S33: 46062 | T33: 46069 | U33: 46076 | V33: 46083 | W33: 46090 | X33: 46097 | Y33: 46104 | Z33: 46111 | AA33: 46118 | AB33: 46125 | AC33: 46132 | AD33: 46139 | AE33: 46146 | AF33: 46153 | AG33: 46160 | AH33: 46167 | AI33: 46174 | AJ33: 46181 | AK33: 46188 | AL33: 46195 | AM33: 46202 | AN33: 46209 | AO33: 46216 | AP33: 46223 | AQ33: 46230 | AR33: 46237 | AS33: 46244 | AT33: 46251 | AU33: 46258 | AV33: 46265 | AW33: 46272 | AX33: 46279 | AY33: 46286 | AZ33: 46293 | BA33: 46300 | BB33: 46307 | BC33: 46314 | BD33: 46321 | BE33: 46328 | BF33: 46335 | BG33: 46342 | BH33: 46349 | BI33: 46356 | BJ33: 46363 | BK33: 46370 | BL33: 46377 | BM33: 46384 | BO33: Kms recorridos x semana
BS34: KM SEM
A35: ASM-002HiluxMedio Ambiente ZH-3163-B | D35: =IF(D8-C8>0,D8-C8,"") -> 188 | E35: =IF(E8-D8>0,E8-D8,"") -> 113 | F35: =IF(F8-E8>0,F8-E8,"") -> 140 | G35: =IF(G8-F8>0,G8-F8,"") -> 154 | H35: =IF(H8-G8>0,H8-G8,"") -> 63 | I35: =IF(I8-H8>0,I8-H8,"") -> 137 | J35: =IF(J8-I8>0,J8-I8,"") -> 97 | K35: =IF(K8-J8>0,K8-J8,"") -> 189 | ... M35: =IF(M8-L8>0,M8-L8,"") -> 44 | N35: =IF(O8-N8>0,O8-N8,"") -> 1 | O35: =IF(P8-O8>0,P8-O8,"") -> 6 | P35: =IF(Q8-P8>0,Q8-P8,"") | Q35: =IF(R8-Q8>0,R8-Q8,"") | R35: =IF(S8-R8>0,S8-R8,"") -> 90.5 | S35: =IF(T8-S8>0,T8-S8,"") -> 90.5 | T35: =IF(U8-T8>0,U8-T8,"") -> 251 | U35: =IF(V8-U8>0,V8-U8,"") -> 160 | ... BC35: =IF(BD8-BC8>0,BD8-BC8,"") | BO35: =MAX(N35:BM35) -> 251 | BS35: =+BO35 -> 251
A36: ASM-006FrontierMedio Ambiente ZH-3161-B | D36: =IF(D9-C9>0,D9-C9,"") -> 168 | E36: =IF(E9-D9>0,E9-D9,"") -> 149 | F36: =IF(F9-E9>0,F9-E9,"") -> 212 | G36: =IF(G9-F9>0,G9-F9,"") -> 181 | H36: =IF(H9-G9>0,H9-G9,"") -> 59 | I36: =IF(I9-H9>0,I9-H9,"") -> 59 | J36: =IF(J9-I9>0,J9-I9,"") -> 338.5 | K36: =IF(K9-J9>0,K9-J9,"") -> 338.5 | ... M36: =IF(M9-L9>0,M9-L9,"") -> 60.5 | N36: =IF(O9-N9>0,O9-N9,"") -> 100 | O36: =IF(P9-O9>0,P9-O9,"") -> 107 | P36: =IF(Q9-P9>0,Q9-P9,"") -> 118 | Q36: =IF(R9-Q9>0,R9-Q9,"") -> 118 | R36: =IF(S9-R9>0,S9-R9,"") -> 117 | S36: =IF(T9-S9>0,T9-S9,"") -> 188 | T36: =IF(U9-T9>0,U9-T9,"") -> 129 | U36: =IF(V9-U9>0,V9-U9,"") -> 117 | ... AP36: =IF(AQ9-AP9>0,AQ9-AP9,"") | AQ36: =IF(AR10-AQ10>0,AR10-AQ10,"") | AR36: =IF(AS10-AR10>0,AS10-AR10,"") | AS36: =IF(AT10-AS10>0,AT10-AS10,"") | AT36: =IF(AU10-AT10>0,AU10-AT10,"") | AU36: =IF(AV10-AU10>0,AV10-AU10,"") | AV36: =IF(AW10-AV10>0,AW10-AV10,"") | AW36: =IF(AX10-AW10>0,AX10-AW10,"") | AX36: =IF(AY10-AX10>0,AY10-AX10,"") | ... BC36: =IF(BD10-BC10>0,BD10-BC10,"") | BO36: =MAX(N36:BM36) -> 315 | BS36: =+BO36 -> 315
A37: ASM-007NP 300LaboratorioZH-3160-B | D37: =IF(D10-C10>0,D10-C10,"") -> 105 | E37: =IF(E10-D10>0,E10-D10,"") -> 77 | F37: =IF(F10-E10>0,F10-E10,"") -> 77 | G37: =IF(G10-F10>0,G10-F10,"") -> 77 | H37: =IF(H10-G10>0,H10-G10,"") -> 77 | I37: =IF(I10-H10>0,I10-H10,"") -> 77 | J37: =IF(J10-I10>0,J10-I10,"") -> 77 | K37: =IF(K10-J10>0,K10-J10,"") -> 77 | ... M37: =IF(M10-L10>0,M10-L10,"") -> 76 | N37: =IF(O10-N10>0,O10-N10,"") -> 59 | O37: =IF(P10-O10>0,P10-O10,"") -> 59 | P37: =IF(Q10-P10>0,Q10-P10,"") -> 59 | Q37: =IF(R10-Q10>0,R10-Q10,"") -> 59 | R37: =IF(S10-R10>0,S10-R10,"") -> 59 | S37: =IF(T10-S10>0,T10-S10,"") -> 59 | T37: =IF(U10-T10>0,U10-T10,"") -> 59 | U37: =IF(V10-U10>0,V10-U10,"") -> 59 | ... AP37: =IF(AQ10-AP10>0,AQ10-AP10,"") | AQ37: =IF(AR11-AQ11>0,AR11-AQ11,"") | AR37: =IF(AS11-AR11>0,AS11-AR11,"") | AS37: =IF(AT11-AS11>0,AT11-AS11,"") | AT37: =IF(AU11-AT11>0,AU11-AT11,"") | AU37: =IF(AV11-AU11>0,AV11-AU11,"") | AV37: =IF(AW11-AV11>0,AW11-AV11,"") | AW37: =IF(AX11-AW11>0,AX11-AW11,"") | AX37: =IF(AY11-AX11>0,AY11-AX11,"") | ... BC37: =IF(BD11-BC11>0,BD11-BC11,"") | BO37: =MAX(N37:BM37) -> 105 | BS37: =+BO37 -> 105
A38: ASM-008HiluxOperación Mina TP-0477-H | D38: =IF(D11-C11>0,D11-C11,"") -> 491.5 | E38: =IF(E11-D11>0,E11-D11,"") -> 296 | F38: =IF(F11-E11>0,F11-E11,"") -> 756 | G38: =IF(G11-F11>0,G11-F11,"") -> 493 | H38: =IF(H11-G11>0,H11-G11,"") -> 484 | I38: =IF(I11-H11>0,I11-H11,"") -> 488 | J38: =IF(J11-I11>0,J11-I11,"") -> 432 | K38: =IF(K11-J11>0,K11-J11,"") -> 432 | ... M38: =IF(M11-L11>0,M11-L11,"") -> 355.5 | N38: =IF(O11-N11>0,O11-N11,"") -> 463 | O38: =IF(P11-O11>0,P11-O11,"") -> 712 | P38: =IF(Q11-P11>0,Q11-P11,"") -> 302 | Q38: =IF(R11-Q11>0,R11-Q11,"") -> 302 | R38: =IF(S11-R11>0,S11-R11,"") -> 301 | S38: =IF(T11-S11>0,T11-S11,"") -> 770 | T38: =IF(U11-T11>0,U11-T11,"") -> 420 | U38: =IF(V11-U11>0,V11-U11,"") -> 420 | ... AP38: =IF(AQ11-AP11>0,AQ11-AP11,"") | AQ38: =IF(AR12-AQ12>0,AR12-AQ12,"") | AR38: =IF(AS12-AR12>0,AS12-AR12,"") | AS38: =IF(AT12-AS12>0,AT12-AS12,"") | AT38: =IF(AU12-AT12>0,AU12-AT12,"") | AU38: =IF(AV12-AU12>0,AV12-AU12,"") | AV38: =IF(AW12-AV12>0,AW12-AV12,"") | AW38: =IF(AX12-AW12>0,AX12-AW12,"") | AX38: =IF(AY12-AX12>0,AY12-AX12,"") | ... BC38: =IF(BD12-BC12>0,BD12-BC12,"") | BO38: =MAX(N38:BM38) -> 770 | BS38: =+BO38 -> 770
A39: ASM-009NissanVersaVEH-746-D | D39: =IF(D12-C12>0,D12-C12,"") -> 667 | E39: =IF(E12-D12>0,E12-D12,"") -> 1013 | F39: =IF(F12-E12>0,F12-E12,"") -> 932 | G39: =IF(G12-F12>0,G12-F12,"") -> 509 | H39: =IF(H12-G12>0,H12-G12,"") -> 509 | I39: =IF(I12-H12>0,I12-H12,"") -> 793 | J39: =IF(J12-I12>0,J12-I12,"") -> 19 | K39: =IF(K12-J12>0,K12-J12,"") -> 1559 | ... M39: =IF(M12-L12>0,M12-L12,"") -> 768.5 | N39: =IF(O12-N12>0,O12-N12,"") -> 583 | O39: =IF(P12-O12>0,P12-O12,"") -> 583 | P39: =IF(Q12-P12>0,Q12-P12,"") -> 1019 | Q39: =IF(R12-Q12>0,R12-Q12,"") -> 1019 | R39: =IF(S12-R12>0,S12-R12,"") -> 1018 | S39: =IF(T12-S12>0,T12-S12,"") -> 896 | T39: =IF(U12-T12>0,U12-T12,"") -> 732 | U39: =IF(V12-U12>0,V12-U12,"") -> 1269 | ... AP39: =IF(AQ12-AP12>0,AQ12-AP12,"") | AQ39: =IF(AR13-AQ13>0,AR13-AQ13,"") | AR39: =IF(AS13-AR13>0,AS13-AR13,"") | AS39: =IF(AT13-AS13>0,AT13-AS13,"") | AT39: =IF(AU13-AT13>0,AU13-AT13,"") | AU39: =IF(AV13-AU13>0,AV13-AU13,"") | AV39: =IF(AW13-AV13>0,AW13-AV13,"") | AW39: =IF(AX13-AW13>0,AX13-AW13,"") | AX39: =IF(AY13-AX13>0,AY13-AX13,"") | ... BC39: =IF(BD13-BC13>0,BD13-BC13,"") | BO39: =MAX(N39:BM39) -> 1269 | BS39: =+BO39 -> 1269
A40: ASM-010ChevroletAveoUXS-682-E | D40: =IF(D13-C13>0,D13-C13,"") -> 836.5 | E40: =IF(E13-D13>0,E13-D13,"") -> 459 | F40: =IF(F13-E13>0,F13-E13,"") -> 1552 | G40: =IF(G13-F13>0,G13-F13,"") -> 838 | H40: =IF(H13-G13>0,H13-G13,"") -> 531 | I40: =IF(I13-H13>0,I13-H13,"") -> 531 | J40: =IF(J13-I13>0,J13-I13,"") -> 531 | K40: =IF(K13-J13>0,K13-J13,"") -> 531 | ... M40: =IF(M13-L13>0,M13-L13,"") -> 531 | N40: =IF(O13-N13>0,O13-N13,"") -> 531 | O40: =IF(P13-O13>0,P13-O13,"") -> 532 | P40: =IF(Q13-P13>0,Q13-P13,"") -> 545 | Q40: =IF(R13-Q13>0,R13-Q13,"") -> 545 | R40: =IF(S13-R13>0,S13-R13,"") -> 546 | S40: =IF(T13-S13>0,T13-S13,"") | T40: =IF(U13-T13>0,U13-T13,"") -> 1602 | U40: =IF(V13-U13>0,V13-U13,"") -> 1250 | ... AP40: =IF(AQ13-AP13>0,AQ13-AP13,"") | AQ40: =IF(AR14-AQ14>0,AR14-AQ14,"") | AR40: =IF(AS14-AR14>0,AS14-AR14,"") | AS40: =IF(AT14-AS14>0,AT14-AS14,"") | AT40: =IF(AU14-AT14>0,AU14-AT14,"") | AU40: =IF(AV14-AU14>0,AV14-AU14,"") | AV40: =IF(AW14-AV14>0,AW14-AV14,"") | AW40: =IF(AX14-AW14>0,AX14-AW14,"") | AX40: =IF(AY14-AX14>0,AY14-AX14,"") | ... BC40: =IF(BD14-BC14>0,BD14-BC14,"") | BO40: =MAX(N40:BM40) -> 1602 | BS40: =+BO40 -> 1602
A41: ASM-011Ram 4000Mantenimiento PlantaZH-3152-B | D41: =IF(D14-C14>0,D14-C14,"") -> 97 | E41: =IF(E14-D14>0,E14-D14,"") -> 145 | F41: =IF(F14-E14>0,F14-E14,"") -> 91 | G41: =IF(G14-F14>0,G14-F14,"") -> 91 | H41: =IF(H14-G14>0,H14-G14,"") -> 90 | I41: =IF(I14-H14>0,I14-H14,"") -> 309 | J41: =IF(J14-I14>0,J14-I14,"") -> 142 | K41: =IF(K14-J14>0,K14-J14,"") -> 142 | ... M41: =IF(M14-L14>0,M14-L14,"") -> 42 | N41: =IF(O14-N14>0,O14-N14,"") -> 108 | O41: =IF(P14-O14>0,P14-O14,"") -> 108 | P41: =IF(Q14-P14>0,Q14-P14,"") -> 104 | Q41: =IF(R14-Q14>0,R14-Q14,"") -> 104 | R41: =IF(S14-R14>0,S14-R14,"") -> 104 | S41: =IF(T14-S14>0,T14-S14,"") -> 122 | T41: =IF(U14-T14>0,U14-T14,"") -> 395 | U41: =IF(V14-U14>0,V14-U14,"") -> 97 | ... AP41: =IF(AQ14-AP14>0,AQ14-AP14,"") | AQ41: =IF(AR15-AQ15>0,AR15-AQ15,"") | AR41: =IF(AS15-AR15>0,AS15-AR15,"") | AS41: =IF(AT15-AS15>0,AT15-AS15,"") | AT41: =IF(AU15-AT15>0,AU15-AT15,"") | AU41: =IF(AV15-AU15>0,AV15-AU15,"") | AV41: =IF(AW15-AV15>0,AW15-AV15,"") | AW41: =IF(AX15-AW15>0,AX15-AW15,"") | AX41: =IF(AY15-AX15>0,AY15-AX15,"") | ... BC41: =IF(BD15-BC15>0,BD15-BC15,"") | BO41: =MAX(N41:BM41) -> 395 | BS41: =+BO41 -> 395
A42: ASM-012L200 Gerencia GeneralZD-1550-B | D42: =IF(D15-C15>0,D15-C15,"") -> 327 | E42: =IF(E15-D15>0,E15-D15,"") -> 69 | F42: =IF(F15-E15>0,F15-E15,"") -> 69 | G42: =IF(G15-F15>0,G15-F15,"") -> 69 | H42: =IF(H15-G15>0,H15-G15,"") -> 330 | I42: =IF(I15-H15>0,I15-H15,"") -> 330 | J42: =IF(J15-I15>0,J15-I15,"") -> 91.5 | K42: =IF(K15-J15>0,K15-J15,"") -> 91.5 | ... M42: =IF(M15-L15>0,M15-L15,"") -> 450 | N42: =IF(O15-N15>0,O15-N15,"") -> 1014 | O42: =IF(P15-O15>0,P15-O15,"") -> 1014 | P42: =IF(Q15-P15>0,Q15-P15,"") -> 1014 | Q42: =IF(R15-Q15>0,R15-Q15,"") -> 1014 | R42: =IF(S15-R15>0,S15-R15,"") -> 1014 | S42: =IF(T15-S15>0,T15-S15,"") -> 1014 | T42: =IF(U15-T15>0,U15-T15,"") | U42: =IF(V15-U15>0,V15-U15,"") -> 153 | ... AP42: =IF(AQ15-AP15>0,AQ15-AP15,"") | AQ42: =IF(AR16-AQ16>0,AR16-AQ16,"") | AR42: =IF(AS16-AR16>0,AS16-AR16,"") | AS42: =IF(AT16-AS16>0,AT16-AS16,"") | AT42: =IF(AU16-AT16>0,AU16-AT16,"") | AU42: =IF(AV16-AU16>0,AV16-AU16,"") | AV42: =IF(AW16-AV16>0,AW16-AV16,"") | AW42: =IF(AX16-AW16>0,AX16-AW16,"") | AX42: =IF(AY16-AX16>0,AY16-AX16,"") | ... BC42: =IF(BD16-BC16>0,BD16-BC16,"") | BO42: =MAX(N42:BM42) -> 1014 | BS42: =+BO42 -> 1014
A43: ASM-013L200 Seguridad IndustrialZD-1551-B | D43: =IF(D16-C16>0,D16-C16,"") -> 536 | E43: =IF(E16-D16>0,E16-D16,"") -> 140 | F43: =IF(F16-E16>0,F16-E16,"") -> 327 | G43: =IF(G16-F16>0,G16-F16,"") -> 78 | H43: =IF(H16-G16>0,H16-G16,"") -> 175 | I43: =IF(I16-H16>0,I16-H16,"") -> 175 | J43: =IF(J16-I16>0,J16-I16,"") -> 99.5 | K43: =IF(K16-J16>0,K16-J16,"") -> 99.5 | ... M43: =IF(M16-L16>0,M16-L16,"") -> 100 | N43: =IF(O16-N16>0,O16-N16,"") -> 100 | O43: =IF(P16-O16>0,P16-O16,"") -> 100 | P43: =IF(Q16-P16>0,Q16-P16,"") -> 114 | Q43: =IF(R16-Q16>0,R16-Q16,"") -> 114 | R43: =IF(S16-R16>0,S16-R16,"") -> 114 | S43: =IF(T16-S16>0,T16-S16,"") -> 257 | T43: =IF(U16-T16>0,U16-T16,"") -> 220 | U43: =IF(V16-U16>0,V16-U16,"") -> 174 | ... AP43: =IF(AQ16-AP16>0,AQ16-AP16,"") | AQ43: =IF(AR17-AQ17>0,AR17-AQ17,"") | AR43: =IF(AS17-AR17>0,AS17-AR17,"") | AS43: =IF(AT17-AS17>0,AT17-AS17,"") | AT43: =IF(AU17-AT17>0,AU17-AT17,"") | AU43: =IF(AV17-AU17>0,AV17-AU17,"") | AV43: =IF(AW17-AV17>0,AW17-AV17,"") | AW43: =IF(AX17-AW17>0,AX17-AW17,"") | AX43: =IF(AY17-AX17>0,AY17-AX17,"") | ... BC43: =IF(BD17-BC17>0,BD17-BC17,"") | BO43: =MAX(N43:BM43) -> 307 | BS43: =+BO43 -> 307
...
